Workbook

Sheet Cas 2011-2025
A1: Année | B1: Catégorie | C1: Station | D1: SSP n° | E1: SSP | F1: Plainte | G1: Diagnostic générique | H1: Diagnstic principal | I1: Diagnostics différentiels | J1: Description | K1: Anamnèse | L1: Status | M1: Management | N1: Diagnstic principal (original) | O1: SSP attendu (par n°) | P1: Concordance n° ↔ libellé | Q1: Écart vs backup (Feuil1!E) | R1: À vérifier | S1: Cohérence diag. générique ↔ principal | T1: Détails cohérence | U1: Key (2013-2017 match) | V1: Desc (C13-17) | W1: Anamnèse (C13-17) | X1: Status (C13-17) | Y1: DD (C13-17) | Z1: PEC (C13-17) | AA1: Examens compl. (C13-17) | AB1: Key (norm) | AC1: Diag norm (1) | AD1: Diag norm (2) | AE1: Diag norm (3) | AF1: Diag norm (4)
A2: 2011 | B2: ❤️ Cardiologie / Vasculaire | D2: 10 | E2: =IF(D2="","",IFERROR(INDEX(SSP!$E$2:$E$266, MATCH(D2, SSP!$F$2:$F$266, 0)),"")) -> Douleur (toutes localisations et types confondus) | F2: =Feuil1!E2 -> Douleur jambe | G2: Artériopathie des membres inférieurs | H2: AOMI | J2: Homme d'âge moyen avec douleur soudaine et intense à la jambe droite depuis 2 heures pendant le jardinage. Allongé sur le lit et incapable de marcher. | K2: Anamnèse, examen, procédures supplémentaires. Héparine administrée, transfert au laboratoire de cathétérisme. Disparition des pulsations à la jambe droite, héparine administrée. | N2: AOMI | O2: =IFERROR(_xlfn.XLOOKUP($D2, SSP!$F:$F, SSP!$E:$E, "Inconnu"), "") -> Douleur (toutes localisations et types confondus) | P2: =IF(OR(E2="", O2=""), "", IF(LOWER(E2)=LOWER(O2), "OK", "⚠️ Libellé ≠ n°")) -> OK | Q2: =IF(Feuil1!$E2="", "", IF(LOWER(Feuil1!$E2)=LOWER(E2), "Identique", "Différent")) -> Différent | R2: =IF(OR(P2="⚠️ Libellé ≠ n°", O2="Inconnu"), "⚠️", IF(Q2="Différent", "ℹ️", "")) -> ℹ️ | S2: {=_xlfn.LET(_xlpm.genCat,IFERROR(LOWER(TRIM(G2)),""),_xlpm.principal,IFERROR(LOWER(TRIM(H2)),""),_xlpm.orig,IFERROR(LOWER(TRIM(N2)),""),IF(OR(_xlpm.genCat="",_xlpm.principal=""),"",IF(LEFT(LOWER(G2),5)="autre","OK (Autre)",IF(OR(ISNUMBER(SEARCH(_xlpm.genCat,_xlpm.principal)),ISNUMBER(SEARCH(_xlpm.principal,_xlpm.genCat)),AND(_xlpm.orig<>"",OR(ISNUMBER(SEARCH(_xlpm.genCat,_xlpm.orig)),ISNUMBER(SEARCH(_xlpm.orig,_xlpm.genCat))))),"OK","⚠️ À vérifier"))))} -> ⚠️ À vérifier | T2: =IF(S2="","",IF(S2="OK (Autre)","Diagnostic générique = 'Autre – …'",IF(S2="OK","Concordance générique/principal","Écart entre générique et principal"))) -> Écart entre générique et principal | U2: {=_xlfn.LET(_xlpm.yr, A2, _xlpm.diag, IF(N2<>"", N2, H2), _xlpm.base, TRIM(SUBSTITUTE(SUBSTITUTE(SUBSTITUTE(SUBSTITUTE(_xlpm.diag,"•"," "),CHAR(160)," "),CHAR(10)," ")," "," ")), LOWER(_xlpm.yr&"|"&_xlpm.base))} -> 2011|aomi | V2: =IFERROR(_xlfn.XLOOKUP($AB2,'Cas 2013-2017'!$K:$K,'Cas 2013-2017'!$D:$D,""),"") | W2: =IFERROR(_xlfn.XLOOKUP($AB2,'Cas 2013-2017'!$K:$K,'Cas 2013-2017'!$E:$E,""),"") | X2: =IFERROR(_xlfn.XLOOKUP($AB2,'Cas 2013-2017'!$K:$K,'Cas 2013-2017'!$F:$F,""),"") | Y2: =IFERROR(_xlfn.XLOOKUP($AB2,'Cas 2013-2017'!$K:$K,'Cas 2013-2017'!$G:$G,""),"") | Z2: =IFERROR(_xlfn.XLOOKUP($AB2,'Cas 2013-2017'!$K:$K,'Cas 2013-2017'!$I:$I,""),"") | AA2: =IFERROR(_xlfn.XLOOKUP($AB2,'Cas 2013-2017'!$K:$K,'Cas 2013-2017'!$H:$H,""),"") | AB2: =LOWER($A2 & "|" & $AF2) -> 2011|arteriopathie des membres inferieurs | AC2: =TRIM(SUBSTITUTE(SUBSTITUTE(SUBSTITUTE(SUBSTITUTE(" " & LOWER(TRIM(IF($N2<>"", $N2, $H2))) & " ", " aomi ", " arteriopathie des membres inferieurs "), " hta ", " hypertension arterielle "), " saos ", " syndrome d'apnees obstructives du sommeil "), " rgo ", " reflux gastro-oesophagien ") ) -> arteriopathie des membres inferieurs | AD2: =TRIM(SUBSTITUTE(SUBSTITUTE(SUBSTITUTE(SUBSTITUTE(" " & LOWER(TRIM($AC2)) & " ", " oacr ", " occlusion de l'artere centrale de la retine "), " hsd ", " hematome sous-dural "), " fa ", " fibrillation auriculaire "), " ep ", " embolie pulmonaire ") ) -> arteriopathie des membres inferieurs | AE2: {=_xlfn.LET(_xlpm.base, " " & LOWER(TRIM($AD2)) & " ", _xlpm.s1, SUBSTITUTE(_xlpm.base, " ic ", " insuffisance cardiaque "), _xlpm.s2, SUBSTITUTE(_xlpm.s1, " avc ", " accident vasculaire cerebral "), _xlpm.s3, SUBSTITUTE(_xlpm.s2, " hsa ", " hemorragie sous-arachnoidienne "), _xlpm.s4, SUBSTITUTE(_xlpm.s3, " htp ", " hypertension pulmonaire "), _xlpm.s5, SUBSTITUTE(_xlpm.s4, " bpco ", " bronchopneumopathie chronique obstructive "), _xlpm.s6, SUBSTITUTE(_xlpm.s5, " dmla ", " degenerescence maculaire liee a l age "), TRIM(_xlpm.s6))} -> arteriopathie des membres inferieurs | AF2: {=_xlfn.LET(_xlpm.base, " " & LOWER(TRIM($AE2)) & " ", _xlpm.s1, SUBSTITUTE(_xlpm.base, " omi ", " oedemes des membres inferieurs "), _xlpm.s2, SUBSTITUTE(_xlpm.s1, " idm ", " infarctus du myocarde "), _xlpm.s3, SUBSTITUTE(_xlpm.s2, " tvp ", " thrombose veineuse profonde "), _xlpm.s4, SUBSTITUTE(_xlpm.s3, " geu ", " grossesse extra-uterine "), _xlpm.s5, SUBSTITUTE(_xlpm.s4, " fuo ", " fievre d origine indeterminee "), TRIM(_xlpm.s5))} -> arteriopathie des membres inferieurs
A3: 2011 | B3: ❤️ Cardiologie / Vasculaire | D3: 44 | E3: =IF(D3="","",IFERROR(INDEX(SSP!$E$2:$E$266, MATCH(D3, SSP!$F$2:$F$266, 0)),"")) -> Douleur thoracique | F3: =Feuil1!E3 -> Douleur thoracique | G3: Péricardite | H3: Péricardite | J3: Homme au service des urgences avec douleur thoracique, respiratoire, améliorée par la flexion en avant. | K3: À l'ECG, élévation du segment ST de V1 à V6, ne peut être examiné en position allongée. Antécédents d'infection. | N3: Péricardite | O3: =IFERROR(_xlfn.XLOOKUP($D3, SSP!$F:$F, SSP!$E:$E, "Inconnu"), "") -> Douleur thoracique | P3: =IF(OR(E3="", O3=""), "", IF(LOWER(E3)=LOWER(O3), "OK", "⚠️ Libellé ≠ n°")) -> OK | Q3: =IF(Feuil1!$E3="", "", IF(LOWER(Feuil1!$E3)=LOWER(E3), "Identique", "Différent")) -> Identique | R3: =IF(OR(P3="⚠️ Libellé ≠ n°", O3="Inconnu"), "⚠️", IF(Q3="Différent", "ℹ️", "")) | S3: {=_xlfn.LET(_xlpm.genCat,IFERROR(LOWER(TRIM(G3)),""),_xlpm.principal,IFERROR(LOWER(TRIM(H3)),""),_xlpm.orig,IFERROR(LOWER(TRIM(N3)),""),IF(OR(_xlpm.genCat="",_xlpm.principal=""),"",IF(LEFT(LOWER(G3),5)="autre","OK (Autre)",IF(OR(ISNUMBER(SEARCH(_xlpm.genCat,_xlpm.principal)),ISNUMBER(SEARCH(_xlpm.principal,_xlpm.genCat)),AND(_xlpm.orig<>"",OR(ISNUMBER(SEARCH(_xlpm.genCat,_xlpm.orig)),ISNUMBER(SEARCH(_xlpm.orig,_xlpm.genCat))))),"OK","⚠️ À vérifier"))))} -> OK | T3: =IF(S3="","",IF(S3="OK (Autre)","Diagnostic générique = 'Autre – …'",IF(S3="OK","Concordance générique/principal","Écart entre générique et principal"))) -> Concordance générique/principal | U3: {=_xlfn.LET(_xlpm.yr, A3, _xlpm.diag, IF(N3<>"", N3, H3), _xlpm.base, TRIM(SUBSTITUTE(SUBSTITUTE(SUBSTITUTE(SUBSTITUTE(_xlpm.diag,"•"," "),CHAR(160)," "),CHAR(10)," ")," "," ")), LOWER(_xlpm.yr&"|"&_xlpm.base))} -> 2011|péricardite | V3: =IFERROR(_xlfn.XLOOKUP($AB3,'Cas 2013-2017'!$K:$K,'Cas 2013-2017'!$D:$D,""),"") | W3: =IFERROR(_xlfn.XLOOKUP($AB3,'Cas 2013-2017'!$K:$K,'Cas 2013-2017'!$E:$E,""),"") | X3: =IFERROR(_xlfn.XLOOKUP($AB3,'Cas 2013-2017'!$K:$K,'Cas 2013-2017'!$F:$F,""),"") | Y3: =IFERROR(_xlfn.XLOOKUP($AB3,'Cas 2013-2017'!$K:$K,'Cas 2013-2017'!$G:$G,""),"") | Z3: =IFERROR(_xlfn.XLOOKUP($AB3,'Cas 2013-2017'!$K:$K,'Cas 2013-2017'!$I:$I,""),"") | AA3: =IFERROR(_xlfn.XLOOKUP($AB3,'Cas 2013-2017'!$K:$K,'Cas 2013-2017'!$H:$H,""),"") | AB3: =LOWER($A3 & "|" & $AF3) -> 2011|péricardite | AC3: =TRIM(SUBSTITUTE(SUBSTITUTE(SUBSTITUTE(SUBSTITUTE(" " & LOWER(TRIM(IF($N3<>"", $N3, $H3))) & " ", " aomi ", " arteriopathie des membres inferieurs "), " hta ", " hypertension arterielle "), " saos ", " syndrome d'apnees obstructives du sommeil "), " rgo ", " reflux gastro-oesophagien ") ) -> péricardite | AD3: =TRIM(SUBSTITUTE(SUBSTITUTE(SUBSTITUTE(SUBSTITUTE(" " & LOWER(TRIM($AC3)) & " ", " oacr ", " occlusion de l'artere centrale de la retine "), " hsd ", " hematome sous-dural "), " fa ", " fibrillation auriculaire "), " ep ", " embolie pulmonaire ") ) -> péricardite | AE3: {=_xlfn.LET(_xlpm.base, " " & LOWER(TRIM($AD3)) & " ", _xlpm.s1, SUBSTITUTE(_xlpm.base, " ic ", " insuffisance cardiaque "), _xlpm.s2, SUBSTITUTE(_xlpm.s1, " avc ", " accident vasculaire cerebral "), _xlpm.s3, SUBSTITUTE(_xlpm.s2, " hsa ", " hemorragie sous-arachnoidienne "), _xlpm.s4, SUBSTITUTE(_xlpm.s3, " htp ", " hypertension pulmonaire "), _xlpm.s5, SUBSTITUTE(_xlpm.s4, " bpco ", " bronchopneumopathie chronique obstructive "), _xlpm.s6, SUBSTITUTE(_xlpm.s5, " dmla ", " degenerescence maculaire liee a l age "), TRIM(_xlpm.s6))} -> péricardite | AF3: {=_xlfn.LET(_xlpm.base, " " & LOWER(TRIM($AE3)) & " ", _xlpm.s1, SUBSTITUTE(_xlpm.base, " omi ", " oedemes des membres inferieurs "), _xlpm.s2, SUBSTITUTE(_xlpm.s1, " idm ", " infarctus du myocarde "), _xlpm.s3, SUBSTITUTE(_xlpm.s2, " tvp ", " thrombose veineuse profonde "), _xlpm.s4, SUBSTITUTE(_xlpm.s3, " geu ", " grossesse extra-uterine "), _xlpm.s5, SUBSTITUTE(_xlpm.s4, " fuo ", " fievre d origine indeterminee "), TRIM(_xlpm.s5))} -> péricardite
A4: 2011 | B4: ❤️ Cardiologie / Vasculaire | D4: 50 | E4: =IF(D4="","",IFERROR(INDEX(SSP!$E$2:$E$266, MATCH(D4, SSP!$F$2:$F$266, 0)),"")) -> Palpitations | F4: =Feuil1!E4 -> Palpitations | G4: Autre – ️ Cardiologie / Vasculaire | H4: Tachycardie psychogène | I4: Hyperthyroïdie | J4: Jeune femme présentant des palpitations et des tachycardies | K4: ECG normal | N4: Tachycardie psychogène | O4: =IFERROR(_xlfn.XLOOKUP($D4, SSP!$F:$F, SSP!$E:$E, "Inconnu"), "") -> Palpitations | P4: =IF(OR(E4="", O4=""), "", IF(LOWER(E4)=LOWER(O4), "OK", "⚠️ Libellé ≠ n°")) -> OK | Q4: =IF(Feuil1!$E4="", "", IF(LOWER(Feuil1!$E4)=LOWER(E4), "Identique", "Différent")) -> Identique | R4: =IF(OR(P4="⚠️ Libellé ≠ n°", O4="Inconnu"), "⚠️", IF(Q4="Différent", "ℹ️", "")) | S4: {=_xlfn.LET(_xlpm.genCat,IFERROR(LOWER(TRIM(G4)),""),_xlpm.principal,IFERROR(LOWER(TRIM(H4)),""),_xlpm.orig,IFERROR(LOWER(TRIM(N4)),""),IF(OR(_xlpm.genCat="",_xlpm.principal=""),"",IF(LEFT(LOWER(G4),5)="autre","OK (Autre)",IF(OR(ISNUMBER(SEARCH(_xlpm.genCat,_xlpm.principal)),ISNUMBER(SEARCH(_xlpm.principal,_xlpm.genCat)),AND(_xlpm.orig<>"",OR(ISNUMBER(SEARCH(_xlpm.genCat,_xlpm.orig)),ISNUMBER(SEARCH(_xlpm.orig,_xlpm.genCat))))),"OK","⚠️ À vérifier"))))} -> OK (Autre) | T4: =IF(S4="","",IF(S4="OK (Autre)","Diagnostic générique = 'Autre – …'",IF(S4="OK","Concordance générique/principal","Écart entre générique et principal"))) -> Diagnostic générique = 'Autre – …' | U4: {=_xlfn.LET(_xlpm.yr, A4, _xlpm.diag, IF(N4<>"", N4, H4), _xlpm.base, TRIM(SUBSTITUTE(SUBSTITUTE(SUBSTITUTE(SUBSTITUTE(_xlpm.diag,"•"," "),CHAR(160)," "),CHAR(10)," ")," "," ")), LOWER(_xlpm.yr&"|"&_xlpm.base))} -> 2011|tachycardie psychogène | V4: =IFERROR(_xlfn.XLOOKUP($AB4,'Cas 2013-2017'!$K:$K,'Cas 2013-2017'!$D:$D,""),"") | W4: =IFERROR(_xlfn.XLOOKUP($AB4,'Cas 2013-2017'!$K:$K,'Cas 2013-2017'!$E:$E,""),"") | X4: =IFERROR(_xlfn.XLOOKUP($AB4,'Cas 2013-2017'!$K:$K,'Cas 2013-2017'!$F:$F,""),"") | Y4: =IFERROR(_xlfn.XLOOKUP($AB4,'Cas 2013-2017'!$K:$K,'Cas 2013-2017'!$G:$G,""),"") | Z4: =IFERROR(_xlfn.XLOOKUP($AB4,'Cas 2013-2017'!$K:$K,'Cas 2013-2017'!$I:$I,""),"") | AA4: =IFERROR(_xlfn.XLOOKUP($AB4,'Cas 2013-2017'!$K:$K,'Cas 2013-2017'!$H:$H,""),"") | AB4: =LOWER($A4 & "|" & $AF4) -> 2011|tachycardie psychogène | AC4: =TRIM(SUBSTITUTE(SUBSTITUTE(SUBSTITUTE(SUBSTITUTE(" " & LOWER(TRIM(IF($N4<>"", $N4, $H4))) & " ", " aomi ", " arteriopathie des membres inferieurs "), " hta ", " hypertension arterielle "), " saos ", " syndrome d'apnees obstructives du sommeil "), " rgo ", " reflux gastro-oesophagien ") ) -> tachycardie psychogène | AD4: =TRIM(SUBSTITUTE(SUBSTITUTE(SUBSTITUTE(SUBSTITUTE(" " & LOWER(TRIM($AC4)) & " ", " oacr ", " occlusion de l'artere centrale de la retine "), " hsd ", " hematome sous-dural "), " fa ", " fibrillation auriculaire "), " ep ", " embolie pulmonaire ") ) -> tachycardie psychogène | AE4: {=_xlfn.LET(_xlpm.base, " " & LOWER(TRIM($AD4)) & " ", _xlpm.s1, SUBSTITUTE(_xlpm.base, " ic ", " insuffisance cardiaque "), _xlpm.s2, SUBSTITUTE(_xlpm.s1, " avc ", " accident vasculaire cerebral "), _xlpm.s3, SUBSTITUTE(_xlpm.s2, " hsa ", " hemorragie sous-arachnoidienne "), _xlpm.s4, SUBSTITUTE(_xlpm.s3, " htp ", " hypertension pulmonaire "), _xlpm.s5, SUBSTITUTE(_xlpm.s4, " bpco ", " bronchopneumopathie chronique obstructive "), _xlpm.s6, SUBSTITUTE(_xlpm.s5, " dmla ", " degenerescence maculaire liee a l age "), TRIM(_xlpm.s6))} -> tachycardie psychogène | AF4: {=_xlfn.LET(_xlpm.base, " " & LOWER(TRIM($AE4)) & " ", _xlpm.s1, SUBSTITUTE(_xlpm.base, " omi ", " oedemes des membres inferieurs "), _xlpm.s2, SUBSTITUTE(_xlpm.s1, " idm ", " infarctus du myocarde "), _xlpm.s3, SUBSTITUTE(_xlpm.s2, " tvp ", " thrombose veineuse profonde "), _xlpm.s4, SUBSTITUTE(_xlpm.s3, " geu ", " grossesse extra-uterine "), _xlpm.s5, SUBSTITUTE(_xlpm.s4, " fuo ", " fievre d origine indeterminee "), TRIM(_xlpm.s5))} -> tachycardie psychogène
A5: 2011 | B5: ❤️ Cardiologie / Vasculaire | D5: 178 | E5: =IF(D5="","",IFERROR(INDEX(SSP!$E$2:$E$266, MATCH(D5, SSP!$F$2:$F$266, 0)),"")) -> Complications maternelles pendant la grossesse (fièvre, œdème, hypertension, travail prématuré) | F5: =Feuil1!E5 -> Hypertension | G5: Hypertension artérielle | H5: Hypertension artérielle (HTA) | J5: Patient d'environ 57 ans vient en consultation pour un contrôle de la tension artérielle. | K5: Hypertension artérielle depuis 5 ans. Examiner d'autres signes d'insuffisance cardiaque (état pulmonaire et cardiaque complet). Tension artérielle actuellement élevée (environ 159/112), antécédents d'insuffisance cardiaque. Suivi IC et HTA + réadaptation médicamenteuse | N5: HTA | O5: =IFERROR(_xlfn.XLOOKUP($D5, SSP!$F:$F, SSP!$E:$E, "Inconnu"), "") -> Complications maternelles pendant la grossesse (fièvre, œdème, hypertension, travail prématuré) | P5: =IF(OR(E5="", O5=""), "", IF(LOWER(E5)=LOWER(O5), "OK", "⚠️ Libellé ≠ n°")) -> OK | Q5: =IF(Feuil1!$E5="", "", IF(LOWER(Feuil1!$E5)=LOWER(E5), "Identique", "Différent")) -> Différent | R5: =IF(OR(P5="⚠️ Libellé ≠ n°", O5="Inconnu"), "⚠️", IF(Q5="Différent", "ℹ️", "")) -> ℹ️ | S5: {=_xlfn.LET(_xlpm.genCat,IFERROR(LOWER(TRIM(G5)),""),_xlpm.principal,IFERROR(LOWER(TRIM(H5)),""),_xlpm.orig,IFERROR(LOWER(TRIM(N5)),""),IF(OR(_xlpm.genCat="",_xlpm.principal=""),"",IF(LEFT(LOWER(G5),5)="autre","OK (Autre)",IF(OR(ISNUMBER(SEARCH(_xlpm.genCat,_xlpm.principal)),ISNUMBER(SEARCH(_xlpm.principal,_xlpm.genCat)),AND(_xlpm.orig<>"",OR(ISNUMBER(SEARCH(_xlpm.genCat,_xlpm.orig)),ISNUMBER(SEARCH(_xlpm.orig,_xlpm.genCat))))),"OK","⚠️ À vérifier"))))} -> OK | T5: =IF(S5="","",IF(S5="OK (Autre)","Diagnostic générique = 'Autre – …'",IF(S5="OK","Concordance générique/principal","Écart entre générique et principal"))) -> Concordance générique/principal | U5: {=_xlfn.LET(_xlpm.yr, A5, _xlpm.diag, IF(N5<>"", N5, H5), _xlpm.base, TRIM(SUBSTITUTE(SUBSTITUTE(SUBSTITUTE(SUBSTITUTE(_xlpm.diag,"•"," "),CHAR(160)," "),CHAR(10)," ")," "," ")), LOWER(_xlpm.yr&"|"&_xlpm.base))} -> 2011|hta | V5: =IFERROR(_xlfn.XLOOKUP($AB5,'Cas 2013-2017'!$K:$K,'Cas 2013-2017'!$D:$D,""),"") | W5: =IFERROR(_xlfn.XLOOKUP($AB5,'Cas 2013-2017'!$K:$K,'Cas 2013-2017'!$E:$E,""),"") | X5: =IFERROR(_xlfn.XLOOKUP($AB5,'Cas 2013-2017'!$K:$K,'Cas 2013-2017'!$F:$F,""),"") | Y5: =IFERROR(_xlfn.XLOOKUP($AB5,'Cas 2013-2017'!$K:$K,'Cas 2013-2017'!$G:$G,""),"") | Z5: =IFERROR(_xlfn.XLOOKUP($AB5,'Cas 2013-2017'!$K:$K,'Cas 2013-2017'!$I:$I,""),"") | AA5: =IFERROR(_xlfn.XLOOKUP($AB5,'Cas 2013-2017'!$K:$K,'Cas 2013-2017'!$H:$H,""),"") | AB5: =LOWER($A5 & "|" & $AF5) -> 2011|hypertension arterielle | AC5: =TRIM(SUBSTITUTE(SUBSTITUTE(SUBSTITUTE(SUBSTITUTE(" " & LOWER(TRIM(IF($N5<>"", $N5, $H5))) & " ", " aomi ", " arteriopathie des membres inferieurs "), " hta ", " hypertension arterielle "), " saos ", " syndrome d'apnees obstructives du sommeil "), " rgo ", " reflux gastro-oesophagien ") ) -> hypertension arterielle | AD5: =TRIM(SUBSTITUTE(SUBSTITUTE(SUBSTITUTE(SUBSTITUTE(" " & LOWER(TRIM($AC5)) & " ", " oacr ", " occlusion de l'artere centrale de la retine "), " hsd ", " hematome sous-dural "), " fa ", " fibrillation auriculaire "), " ep ", " embolie pulmonaire ") ) -> hypertension arterielle | AE5: {=_xlfn.LET(_xlpm.base, " " & LOWER(TRIM($AD5)) & " ", _xlpm.s1, SUBSTITUTE(_xlpm.base, " ic ", " insuffisance cardiaque "), _xlpm.s2, SUBSTITUTE(_xlpm.s1, " avc ", " accident vasculaire cerebral "), _xlpm.s3, SUBSTITUTE(_xlpm.s2, " hsa ", " hemorragie sous-arachnoidienne "), _xlpm.s4, SUBSTITUTE(_xlpm.s3, " htp ", " hypertension pulmonaire "), _xlpm.s5, SUBSTITUTE(_xlpm.s4, " bpco ", " bronchopneumopathie chronique obstructive "), _xlpm.s6, SUBSTITUTE(_xlpm.s5, " dmla ", " degenerescence maculaire liee a l age "), TRIM(_xlpm.s6))} -> hypertension arterielle | AF5: {=_xlfn.LET(_xlpm.base, " " & LOWER(TRIM($AE5)) & " ", _xlpm.s1, SUBSTITUTE(_xlpm.base, " omi ", " oedemes des membres inferieurs "), _xlpm.s2, SUBSTITUTE(_xlpm.s1, " idm ", " infarctus du myocarde "), _xlpm.s3, SUBSTITUTE(_xlpm.s2, " tvp ", " thrombose veineuse profonde "), _xlpm.s4, SUBSTITUTE(_xlpm.s3, " geu ", " grossesse extra-uterine "), _xlpm.s5, SUBSTITUTE(_xlpm.s4, " fuo ", " fievre d origine indeterminee "), TRIM(_xlpm.s5))} -> hypertension arterielle
A6: 2011 | B6: 🧴 Dermatologie | D6: 93 | E6: =IF(D6="","",IFERROR(INDEX(SSP!$E$2:$E$266, MATCH(D6, SSP!$F$2:$F$266, 0)),"")) -> Macules, papules, pustules, vésicules, ulcères, abcès, bulles, épaississement cutané, nécrose, tumeur cutanée | F6: =Feuil1!E6 -> Éruption cutanée | G6: Psoriasis | H6: Psoriasis | J6: Patient avec psoriasis | K6: Diagnostic avec les images nécessaires. | N6: Psoriasis | O6: =IFERROR(_xlfn.XLOOKUP($D6, SSP!$F:$F, SSP!$E:$E, "Inconnu"), "") -> Macules, papules, pustules, vésicules, ulcères, abcès, bulles, épaississement cutané, nécrose, tumeur cutanée | P6: =IF(OR(E6="", O6=""), "", IF(LOWER(E6)=LOWER(O6), "OK", "⚠️ Libellé ≠ n°")) -> OK | Q6: =IF(Feuil1!$E6="", "", IF(LOWER(Feuil1!$E6)=LOWER(E6), "Identique", "Différent")) -> Différent | R6: =IF(OR(P6="⚠️ Libellé ≠ n°", O6="Inconnu"), "⚠️", IF(Q6="Différent", "ℹ️", "")) -> ℹ️ | S6: {=_xlfn.LET(_xlpm.genCat,IFERROR(LOWER(TRIM(G6)),""),_xlpm.principal,IFERROR(LOWER(TRIM(H6)),""),_xlpm.orig,IFERROR(LOWER(TRIM(N6)),""),IF(OR(_xlpm.genCat="",_xlpm.principal=""),"",IF(LEFT(LOWER(G6),5)="autre","OK (Autre)",IF(OR(ISNUMBER(SEARCH(_xlpm.genCat,_xlpm.principal)),ISNUMBER(SEARCH(_xlpm.principal,_xlpm.genCat)),AND(_xlpm.orig<>"",OR(ISNUMBER(SEARCH(_xlpm.genCat,_xlpm.orig)),ISNUMBER(SEARCH(_xlpm.orig,_xlpm.genCat))))),"OK","⚠️ À vérifier"))))} -> OK | T6: =IF(S6="","",IF(S6="OK (Autre)","Diagnostic générique = 'Autre – …'",IF(S6="OK","Concordance générique/principal","Écart entre générique et principal"))) -> Concordance générique/principal | U6: {=_xlfn.LET(_xlpm.yr, A6, _xlpm.diag, IF(N6<>"", N6, H6), _xlpm.base, TRIM(SUBSTITUTE(SUBSTITUTE(SUBSTITUTE(SUBSTITUTE(_xlpm.diag,"•"," "),CHAR(160)," "),CHAR(10)," ")," "," ")), LOWER(_xlpm.yr&"|"&_xlpm.base))} -> 2011|psoriasis | V6: =IFERROR(_xlfn.XLOOKUP($AB6,'Cas 2013-2017'!$K:$K,'Cas 2013-2017'!$D:$D,""),"") | W6: =IFERROR(_xlfn.XLOOKUP($AB6,'Cas 2013-2017'!$K:$K,'Cas 2013-2017'!$E:$E,""),"") | X6: =IFERROR(_xlfn.XLOOKUP($AB6,'Cas 2013-2017'!$K:$K,'Cas 2013-2017'!$F:$F,""),"") | Y6: =IFERROR(_xlfn.XLOOKUP($AB6,'Cas 2013-2017'!$K:$K,'Cas 2013-2017'!$G:$G,""),"") | Z6: =IFERROR(_xlfn.XLOOKUP($AB6,'Cas 2013-2017'!$K:$K,'Cas 2013-2017'!$I:$I,""),"") | AA6: =IFERROR(_xlfn.XLOOKUP($AB6,'Cas 2013-2017'!$K:$K,'Cas 2013-2017'!$H:$H,""),"") | AB6: =LOWER($A6 & "|" & $AF6) -> 2011|psoriasis | AC6: =TRIM(SUBSTITUTE(SUBSTITUTE(SUBSTITUTE(SUBSTITUTE(" " & LOWER(TRIM(IF($N6<>"", $N6, $H6))) & " ", " aomi ", " arteriopathie des membres inferieurs "), " hta ", " hypertension arterielle "), " saos ", " syndrome d'apnees obstructives du sommeil "), " rgo ", " reflux gastro-oesophagien ") ) -> psoriasis | AD6: =TRIM(SUBSTITUTE(SUBSTITUTE(SUBSTITUTE(SUBSTITUTE(" " & LOWER(TRIM($AC6)) & " ", " oacr ", " occlusion de l'artere centrale de la retine "), " hsd ", " hematome sous-dural "), " fa ", " fibrillation auriculaire "), " ep ", " embolie pulmonaire ") ) -> psoriasis | AE6: {=_xlfn.LET(_xlpm.base, " " & LOWER(TRIM($AD6)) & " ", _xlpm.s1, SUBSTITUTE(_xlpm.base, " ic ", " insuffisance cardiaque "), _xlpm.s2, SUBSTITUTE(_xlpm.s1, " avc ", " accident vasculaire cerebral "), _xlpm.s3, SUBSTITUTE(_xlpm.s2, " hsa ", " hemorragie sous-arachnoidienne "), _xlpm.s4, SUBSTITUTE(_xlpm.s3, " htp ", " hypertension pulmonaire "), _xlpm.s5, SUBSTITUTE(_xlpm.s4, " bpco ", " bronchopneumopathie chronique obstructive "), _xlpm.s6, SUBSTITUTE(_xlpm.s5, " dmla ", " degenerescence maculaire liee a l age "), TRIM(_xlpm.s6))} -> psoriasis | AF6: {=_xlfn.LET(_xlpm.base, " " & LOWER(TRIM($AE6)) & " ", _xlpm.s1, SUBSTITUTE(_xlpm.base, " omi ", " oedemes des membres inferieurs "), _xlpm.s2, SUBSTITUTE(_xlpm.s1, " idm ", " infarctus du myocarde "), _xlpm.s3, SUBSTITUTE(_xlpm.s2, " tvp ", " thrombose veineuse profonde "), _xlpm.s4, SUBSTITUTE(_xlpm.s3, " geu ", " grossesse extra-uterine "), _xlpm.s5, SUBSTITUTE(_xlpm.s4, " fuo ", " fievre d origine indeterminee "), TRIM(_xlpm.s5))} -> psoriasis
A7: 2011 | C7: Entretien motivationnel | D7: 130 | E7: =IF(D7="","",IFERROR(INDEX(SSP!$E$2:$E$266, MATCH(D7, SSP!$F$2:$F$266, 0)),"")) -> Usage non médical de substances, dépendance (tabac, alcool, drogues, jeux, etc.) | F7: =Feuil1!E7 -> Abus d'alcool | G7: Trouble lié aux substances | H7: Addiction | J7: Abus d'alcool | K7: Faire revenir le patient, il voyait pas le problème puisqu'il "ne buvait pas au travail", que 0.51 de vin le soir et ça plus des bières le wee. | N7: Addiction | O7: =IFERROR(_xlfn.XLOOKUP($D7, SSP!$F:$F, SSP!$E:$E, "Inconnu"), "") -> Usage non médical de substances, dépendance (tabac, alcool, drogues, jeux, etc.) | P7: =IF(OR(E7="", O7=""), "", IF(LOWER(E7)=LOWER(O7), "OK", "⚠️ Libellé ≠ n°")) -> OK | Q7: =IF(Feuil1!$E7="", "", IF(LOWER(Feuil1!$E7)=LOWER(E7), "Identique", "Différent")) -> Différent | R7: =IF(OR(P7="⚠️ Libellé ≠ n°", O7="Inconnu"), "⚠️", IF(Q7="Différent", "ℹ️", "")) -> ℹ️ | S7: {=_xlfn.LET(_xlpm.genCat,IFERROR(LOWER(TRIM(G7)),""),_xlpm.principal,IFERROR(LOWER(TRIM(H7)),""),_xlpm.orig,IFERROR(LOWER(TRIM(N7)),""),IF(OR(_xlpm.genCat="",_xlpm.principal=""),"",IF(LEFT(LOWER(G7),5)="autre","OK (Autre)",IF(OR(ISNUMBER(SEARCH(_xlpm.genCat,_xlpm.principal)),ISNUMBER(SEARCH(_xlpm.principal,_xlpm.genCat)),AND(_xlpm.orig<>"",OR(ISNUMBER(SEARCH(_xlpm.genCat,_xlpm.orig)),ISNUMBER(SEARCH(_xlpm.orig,_xlpm.genCat))))),"OK","⚠️ À vérifier"))))} -> ⚠️ À vérifier | T7: =IF(S7="","",IF(S7="OK (Autre)","Diagnostic générique = 'Autre – …'",IF(S7="OK","Concordance générique/principal","Écart entre générique et principal"))) -> Écart entre générique et principal | U7: {=_xlfn.LET(_xlpm.yr, A7, _xlpm.diag, IF(N7<>"", N7, H7), _xlpm.base, TRIM(SUBSTITUTE(SUBSTITUTE(SUBSTITUTE(SUBSTITUTE(_xlpm.diag,"•"," "),CHAR(160)," "),CHAR(10)," ")," "," ")), LOWER(_xlpm.yr&"|"&_xlpm.base))} -> 2011|addiction | V7: =IFERROR(_xlfn.XLOOKUP($AB7,'Cas 2013-2017'!$K:$K,'Cas 2013-2017'!$D:$D,""),"") | W7: =IFERROR(_xlfn.XLOOKUP($AB7,'Cas 2013-2017'!$K:$K,'Cas 2013-2017'!$E:$E,""),"") | X7: =IFERROR(_xlfn.XLOOKUP($AB7,'Cas 2013-2017'!$K:$K,'Cas 2013-2017'!$F:$F,""),"") | Y7: =IFERROR(_xlfn.XLOOKUP($AB7,'Cas 2013-2017'!$K:$K,'Cas 2013-2017'!$G:$G,""),"") | Z7: =IFERROR(_xlfn.XLOOKUP($AB7,'Cas 2013-2017'!$K:$K,'Cas 2013-2017'!$I:$I,""),"") | AA7: =IFERROR(_xlfn.XLOOKUP($AB7,'Cas 2013-2017'!$K:$K,'Cas 2013-2017'!$H:$H,""),"") | AB7: =LOWER($A7 & "|" & $AF7) -> 2011|addiction | AC7: =TRIM(SUBSTITUTE(SUBSTITUTE(SUBSTITUTE(SUBSTITUTE(" " & LOWER(TRIM(IF($N7<>"", $N7, $H7))) & " ", " aomi ", " arteriopathie des membres inferieurs "), " hta ", " hypertension arterielle "), " saos ", " syndrome d'apnees obstructives du sommeil "), " rgo ", " reflux gastro-oesophagien ") ) -> addiction | AD7: =TRIM(SUBSTITUTE(SUBSTITUTE(SUBSTITUTE(SUBSTITUTE(" " & LOWER(TRIM($AC7)) & " ", " oacr ", " occlusion de l'artere centrale de la retine "), " hsd ", " hematome sous-dural "), " fa ", " fibrillation auriculaire "), " ep ", " embolie pulmonaire ") ) -> addiction | AE7: {=_xlfn.LET(_xlpm.base, " " & LOWER(TRIM($AD7)) & " ", _xlpm.s1, SUBSTITUTE(_xlpm.base, " ic ", " insuffisance cardiaque "), _xlpm.s2, SUBSTITUTE(_xlpm.s1, " avc ", " accident vasculaire cerebral "), _xlpm.s3, SUBSTITUTE(_xlpm.s2, " hsa ", " hemorragie sous-arachnoidienne "), _xlpm.s4, SUBSTITUTE(_xlpm.s3, " htp ", " hypertension pulmonaire "), _xlpm.s5, SUBSTITUTE(_xlpm.s4, " bpco ", " bronchopneumopathie chronique obstructive "), _xlpm.s6, SUBSTITUTE(_xlpm.s5, " dmla ", " degenerescence maculaire liee a l age "), TRIM(_xlpm.s6))} -> addiction | AF7: {=_xlfn.LET(_xlpm.base, " " & LOWER(TRIM($AE7)) & " ", _xlpm.s1, SUBSTITUTE(_xlpm.base, " omi ", " oedemes des membres inferieurs "), _xlpm.s2, SUBSTITUTE(_xlpm.s1, " idm ", " infarctus du myocarde "), _xlpm.s3, SUBSTITUTE(_xlpm.s2, " tvp ", " thrombose veineuse profonde "), _xlpm.s4, SUBSTITUTE(_xlpm.s3, " geu ", " grossesse extra-uterine "), _xlpm.s5, SUBSTITUTE(_xlpm.s4, " fuo ", " fievre d origine indeterminee "), TRIM(_xlpm.s5))} -> addiction
A8: 2011 | B8: 🧪 Endocrinologie / Métabolisme | D8: 4 | E8: =IF(D8="","",IFERROR(INDEX(SSP!$E$2:$E$266, MATCH(D8, SSP!$F$2:$F$266, 0)),"")) -> Fatigue, asthénie | F8: =Feuil1!E8 -> Fatigue | G8: Hypothyroïdie | H8: Hypothyroïdie | J8: Jeune femme avec histoire classique : Fatigue, froid, chute de cheveux, sécheresse, bradycardie, prise de poids | N8: Hypothyroidie | O8: =IFERROR(_xlfn.XLOOKUP($D8, SSP!$F:$F, SSP!$E:$E, "Inconnu"), "") -> Fatigue, asthénie | P8: =IF(OR(E8="", O8=""), "", IF(LOWER(E8)=LOWER(O8), "OK", "⚠️ Libellé ≠ n°")) -> OK | Q8: =IF(Feuil1!$E8="", "", IF(LOWER(Feuil1!$E8)=LOWER(E8), "Identique", "Différent")) -> Différent | R8: =IF(OR(P8="⚠️ Libellé ≠ n°", O8="Inconnu"), "⚠️", IF(Q8="Différent", "ℹ️", "")) -> ℹ️ | S8: {=_xlfn.LET(_xlpm.genCat,IFERROR(LOWER(TRIM(G8)),""),_xlpm.principal,IFERROR(LOWER(TRIM(H8)),""),_xlpm.orig,IFERROR(LOWER(TRIM(N8)),""),IF(OR(_xlpm.genCat="",_xlpm.principal=""),"",IF(LEFT(LOWER(G8),5)="autre","OK (Autre)",IF(OR(ISNUMBER(SEARCH(_xlpm.genCat,_xlpm.principal)),ISNUMBER(SEARCH(_xlpm.principal,_xlpm.genCat)),AND(_xlpm.orig<>"",OR(ISNUMBER(SEARCH(_xlpm.genCat,_xlpm.orig)),ISNUMBER(SEARCH(_xlpm.orig,_xlpm.genCat))))),"OK","⚠️ À vérifier"))))} -> OK | T8: =IF(S8="","",IF(S8="OK (Autre)","Diagnostic générique = 'Autre – …'",IF(S8="OK","Concordance générique/principal","Écart entre générique et principal"))) -> Concordance générique/principal | U8: {=_xlfn.LET(_xlpm.yr, A8, _xlpm.diag, IF(N8<>"", N8, H8), _xlpm.base, TRIM(SUBSTITUTE(SUBSTITUTE(SUBSTITUTE(SUBSTITUTE(_xlpm.diag,"•"," "),CHAR(160)," "),CHAR(10)," ")," "," ")), LOWER(_xlpm.yr&"|"&_xlpm.base))} -> 2011|hypothyroidie | V8: =IFERROR(_xlfn.XLOOKUP($AB8,'Cas 2013-2017'!$K:$K,'Cas 2013-2017'!$D:$D,""),"") | W8: =IFERROR(_xlfn.XLOOKUP($AB8,'Cas 2013-2017'!$K:$K,'Cas 2013-2017'!$E:$E,""),"") | X8: =IFERROR(_xlfn.XLOOKUP($AB8,'Cas 2013-2017'!$K:$K,'Cas 2013-2017'!$F:$F,""),"") | Y8: =IFERROR(_xlfn.XLOOKUP($AB8,'Cas 2013-2017'!$K:$K,'Cas 2013-2017'!$G:$G,""),"") | Z8: =IFERROR(_xlfn.XLOOKUP($AB8,'Cas 2013-2017'!$K:$K,'Cas 2013-2017'!$I:$I,""),"") | AA8: =IFERROR(_xlfn.XLOOKUP($AB8,'Cas 2013-2017'!$K:$K,'Cas 2013-2017'!$H:$H,""),"") | AB8: =LOWER($A8 & "|" & $AF8) -> 2011|hypothyroidie | AC8: =TRIM(SUBSTITUTE(SUBSTITUTE(SUBSTITUTE(SUBSTITUTE(" " & LOWER(TRIM(IF($N8<>"", $N8, $H8))) & " ", " aomi ", " arteriopathie des membres inferieurs "), " hta ", " hypertension arterielle "), " saos ", " syndrome d'apnees obstructives du sommeil "), " rgo ", " reflux gastro-oesophagien ") ) -> hypothyroidie | AD8: =TRIM(SUBSTITUTE(SUBSTITUTE(SUBSTITUTE(SUBSTITUTE(" " & LOWER(TRIM($AC8)) & " ", " oacr ", " occlusion de l'artere centrale de la retine "), " hsd ", " hematome sous-dural "), " fa ", " fibrillation auriculaire "), " ep ", " embolie pulmonaire ") ) -> hypothyroidie | AE8: {=_xlfn.LET(_xlpm.base, " " & LOWER(TRIM($AD8)) & " ", _xlpm.s1, SUBSTITUTE(_xlpm.base, " ic ", " insuffisance cardiaque "), _xlpm.s2, SUBSTITUTE(_xlpm.s1, " avc ", " accident vasculaire cerebral "), _xlpm.s3, SUBSTITUTE(_xlpm.s2, " hsa ", " hemorragie sous-arachnoidienne "), _xlpm.s4, SUBSTITUTE(_xlpm.s3, " htp ", " hypertension pulmonaire "), _xlpm.s5, SUBSTITUTE(_xlpm.s4, " bpco ", " bronchopneumopathie chronique obstructive "), _xlpm.s6, SUBSTITUTE(_xlpm.s5, " dmla ", " degenerescence maculaire liee a l age "), TRIM(_xlpm.s6))} -> hypothyroidie | AF8: {=_xlfn.LET(_xlpm.base, " " & LOWER(TRIM($AE8)) & " ", _xlpm.s1, SUBSTITUTE(_xlpm.base, " omi ", " oedemes des membres inferieurs "), _xlpm.s2, SUBSTITUTE(_xlpm.s1, " idm ", " infarctus du myocarde "), _xlpm.s3, SUBSTITUTE(_xlpm.s2, " tvp ", " thrombose veineuse profonde "), _xlpm.s4, SUBSTITUTE(_xlpm.s3, " geu ", " grossesse extra-uterine "), _xlpm.s5, SUBSTITUTE(_xlpm.s4, " fuo ", " fievre d origine indeterminee "), TRIM(_xlpm.s5))} -> hypothyroidie
A9: 2011 | B9: 🧬 Oncologie / Hématologie | D9: 91 | E9: =IF(D9="","",IFERROR(INDEX(SSP!$E$2:$E$266, MATCH(D9, SSP!$F$2:$F$266, 0)),"")) -> Ictère | F9: =Feuil1!E9 -> Ictère | G9: Cancer | H9: Carcinome hépatocellulaire | J9: Homme avec ictère, consommation d'alcool et perte de poids. | N9: Carcinome hépatocellulaire | O9: =IFERROR(_xlfn.XLOOKUP($D9, SSP!$F:$F, SSP!$E:$E, "Inconnu"), "") -> Ictère | P9: =IF(OR(E9="", O9=""), "", IF(LOWER(E9)=LOWER(O9), "OK", "⚠️ Libellé ≠ n°")) -> OK | Q9: =IF(Feuil1!$E9="", "", IF(LOWER(Feuil1!$E9)=LOWER(E9), "Identique", "Différent")) -> Identique | R9: =IF(OR(P9="⚠️ Libellé ≠ n°", O9="Inconnu"), "⚠️", IF(Q9="Différent", "ℹ️", "")) | S9: {=_xlfn.LET(_xlpm.genCat,IFERROR(LOWER(TRIM(G9)),""),_xlpm.principal,IFERROR(LOWER(TRIM(H9)),""),_xlpm.orig,IFERROR(LOWER(TRIM(N9)),""),IF(OR(_xlpm.genCat="",_xlpm.principal=""),"",IF(LEFT(LOWER(G9),5)="autre","OK (Autre)",IF(OR(ISNUMBER(SEARCH(_xlpm.genCat,_xlpm.principal)),ISNUMBER(SEARCH(_xlpm.principal,_xlpm.genCat)),AND(_xlpm.orig<>"",OR(ISNUMBER(SEARCH(_xlpm.genCat,_xlpm.orig)),ISNUMBER(SEARCH(_xlpm.orig,_xlpm.genCat))))),"OK","⚠️ À vérifier"))))} -> ⚠️ À vérifier | T9: =IF(S9="","",IF(S9="OK (Autre)","Diagnostic générique = 'Autre – …'",IF(S9="OK","Concordance générique/principal","Écart entre générique et principal"))) -> Écart entre générique et principal | U9: {=_xlfn.LET(_xlpm.yr, A9, _xlpm.diag, IF(N9<>"", N9, H9), _xlpm.base, TRIM(SUBSTITUTE(SUBSTITUTE(SUBSTITUTE(SUBSTITUTE(_xlpm.diag,"•"," "),CHAR(160)," "),CHAR(10)," ")," "," ")), LOWER(_xlpm.yr&"|"&_xlpm.base))} -> 2011|carcinome hépatocellulaire | V9: =IFERROR(_xlfn.XLOOKUP($AB9,'Cas 2013-2017'!$K:$K,'Cas 2013-2017'!$D:$D,""),"") | W9: =IFERROR(_xlfn.XLOOKUP($AB9,'Cas 2013-2017'!$K:$K,'Cas 2013-2017'!$E:$E,""),"") | X9: =IFERROR(_xlfn.XLOOKUP($AB9,'Cas 2013-2017'!$K:$K,'Cas 2013-2017'!$F:$F,""),"") | Y9: =IFERROR(_xlfn.XLOOKUP($AB9,'Cas 2013-2017'!$K:$K,'Cas 2013-2017'!$G:$G,""),"") | Z9: =IFERROR(_xlfn.XLOOKUP($AB9,'Cas 2013-2017'!$K:$K,'Cas 2013-2017'!$I:$I,""),"") | AA9: =IFERROR(_xlfn.XLOOKUP($AB9,'Cas 2013-2017'!$K:$K,'Cas 2013-2017'!$H:$H,""),"") | AB9: =LOWER($A9 & "|" & $AF9) -> 2011|carcinome hépatocellulaire | AC9: =TRIM(SUBSTITUTE(SUBSTITUTE(SUBSTITUTE(SUBSTITUTE(" " & LOWER(TRIM(IF($N9<>"", $N9, $H9))) & " ", " aomi ", " arteriopathie des membres inferieurs "), " hta ", " hypertension arterielle "), " saos ", " syndrome d'apnees obstructives du sommeil "), " rgo ", " reflux gastro-oesophagien ") ) -> carcinome hépatocellulaire | AD9: =TRIM(SUBSTITUTE(SUBSTITUTE(SUBSTITUTE(SUBSTITUTE(" " & LOWER(TRIM($AC9)) & " ", " oacr ", " occlusion de l'artere centrale de la retine "), " hsd ", " hematome sous-dural "), " fa ", " fibrillation auriculaire "), " ep ", " embolie pulmonaire ") ) -> carcinome hépatocellulaire | AE9: {=_xlfn.LET(_xlpm.base, " " & LOWER(TRIM($AD9)) & " ", _xlpm.s1, SUBSTITUTE(_xlpm.base, " ic ", " insuffisance cardiaque "), _xlpm.s2, SUBSTITUTE(_xlpm.s1, " avc ", " accident vasculaire cerebral "), _xlpm.s3, SUBSTITUTE(_xlpm.s2, " hsa ", " hemorragie sous-arachnoidienne "), _xlpm.s4, SUBSTITUTE(_xlpm.s3, " htp ", " hypertension pulmonaire "), _xlpm.s5, SUBSTITUTE(_xlpm.s4, " bpco ", " bronchopneumopathie chronique obstructive "), _xlpm.s6, SUBSTITUTE(_xlpm.s5, " dmla ", " degenerescence maculaire liee a l age "), TRIM(_xlpm.s6))} -> carcinome hépatocellulaire | AF9: {=_xlfn.LET(_xlpm.base, " " & LOWER(TRIM($AE9)) & " ", _xlpm.s1, SUBSTITUTE(_xlpm.base, " omi ", " oedemes des membres inferieurs "), _xlpm.s2, SUBSTITUTE(_xlpm.s1, " idm ", " infarctus du myocarde "), _xlpm.s3, SUBSTITUTE(_xlpm.s2, " tvp ", " thrombose veineuse profonde "), _xlpm.s4, SUBSTITUTE(_xlpm.s3, " geu ", " grossesse extra-uterine "), _xlpm.s5, SUBSTITUTE(_xlpm.s4, " fuo ", " fievre d origine indeterminee "), TRIM(_xlpm.s5))} -> carcinome hépatocellulaire
A10: 2011 | B10: 🍴 Gastro-entérologie / Hépatologie | D10: 59 | E10: =IF(D10="","",IFERROR(INDEX(SSP!$E$2:$E$266, MATCH(D10, SSP!$F$2:$F$266, 0)),"")) -> Diarrhée | F10: =Feuil1!E10 -> Diarrhée | G10: Gastro-entérite | H10: Diarrhée du voyageur | J10: Jeune femme avec antécédents de voyage, désire un médicament. | N10: Diarrhée du voyageur | O10: =IFERROR(_xlfn.XLOOKUP($D10, SSP!$F:$F, SSP!$E:$E, "Inconnu"), "") -> Diarrhée | P10: =IF(OR(E10="", O10=""), "", IF(LOWER(E10)=LOWER(O10), "OK", "⚠️ Libellé ≠ n°")) -> OK | Q10: =IF(Feuil1!$E10="", "", IF(LOWER(Feuil1!$E10)=LOWER(E10), "Identique", "Différent")) -> Identique | R10: =IF(OR(P10="⚠️ Libellé ≠ n°", O10="Inconnu"), "⚠️", IF(Q10="Différent", "ℹ️", "")) | S10: {=_xlfn.LET(_xlpm.genCat,IFERROR(LOWER(TRIM(G10)),""),_xlpm.principal,IFERROR(LOWER(TRIM(H10)),""),_xlpm.orig,IFERROR(LOWER(TRIM(N10)),""),IF(OR(_xlpm.genCat="",_xlpm.principal=""),"",IF(LEFT(LOWER(G10),5)="autre","OK (Autre)",IF(OR(ISNUMBER(SEARCH(_xlpm.genCat,_xlpm.principal)),ISNUMBER(SEARCH(_xlpm.principal,_xlpm.genCat)),AND(_xlpm.orig<>"",OR(ISNUMBER(SEARCH(_xlpm.genCat,_xlpm.orig)),ISNUMBER(SEARCH(_xlpm.orig,_xlpm.genCat))))),"OK","⚠️ À vérifier"))))} -> ⚠️ À vérifier | T10: =IF(S10="","",IF(S10="OK (Autre)","Diagnostic générique = 'Autre – …'",IF(S10="OK","Concordance générique/principal","Écart entre générique et principal"))) -> Écart entre générique et principal | U10: {=_xlfn.LET(_xlpm.yr, A10, _xlpm.diag, IF(N10<>"", N10, H10), _xlpm.base, TRIM(SUBSTITUTE(SUBSTITUTE(SUBSTITUTE(SUBSTITUTE(_xlpm.diag,"•"," "),CHAR(160)," "),CHAR(10)," ")," "," ")), LOWER(_xlpm.yr&"|"&_xlpm.base))} -> 2011|diarrhée du voyageur | V10: =IFERROR(_xlfn.XLOOKUP($AB10,'Cas 2013-2017'!$K:$K,'Cas 2013-2017'!$D:$D,""),"") | W10: =IFERROR(_xlfn.XLOOKUP($AB10,'Cas 2013-2017'!$K:$K,'Cas 2013-2017'!$E:$E,""),"") | X10: =IFERROR(_xlfn.XLOOKUP($AB10,'Cas 2013-2017'!$K:$K,'Cas 2013-2017'!$F:$F,""),"") | Y10: =IFERROR(_xlfn.XLOOKUP($AB10,'Cas 2013-2017'!$K:$K,'Cas 2013-2017'!$G:$G,""),"") | Z10: =IFERROR(_xlfn.XLOOKUP($AB10,'Cas 2013-2017'!$K:$K,'Cas 2013-2017'!$I:$I,""),"") | AA10: =IFERROR(_xlfn.XLOOKUP($AB10,'Cas 2013-2017'!$K:$K,'Cas 2013-2017'!$H:$H,""),"") | AB10: =LOWER($A10 & "|" & $AF10) -> 2011|diarrhée du voyageur | AC10: =TRIM(SUBSTITUTE(SUBSTITUTE(SUBSTITUTE(SUBSTITUTE(" " & LOWER(TRIM(IF($N10<>"", $N10, $H10))) & " ", " aomi ", " arteriopathie des membres inferieurs "), " hta ", " hypertension arterielle "), " saos ", " syndrome d'apnees obstructives du sommeil "), " rgo ", " reflux gastro-oesophagien ") ) -> diarrhée du voyageur | AD10: =TRIM(SUBSTITUTE(SUBSTITUTE(SUBSTITUTE(SUBSTITUTE(" " & LOWER(TRIM($AC10)) & " ", " oacr ", " occlusion de l'artere centrale de la retine "), " hsd ", " hematome sous-dural "), " fa ", " fibrillation auriculaire "), " ep ", " embolie pulmonaire ") ) -> diarrhée du voyageur | AE10: {=_xlfn.LET(_xlpm.base, " " & LOWER(TRIM($AD10)) & " ", _xlpm.s1, SUBSTITUTE(_xlpm.base, " ic ", " insuffisance cardiaque "), _xlpm.s2, SUBSTITUTE(_xlpm.s1, " avc ", " accident vasculaire cerebral "), _xlpm.s3, SUBSTITUTE(_xlpm.s2, " hsa ", " hemorragie sous-arachnoidienne "), _xlpm.s4, SUBSTITUTE(_xlpm.s3, " htp ", " hypertension pulmonaire "), _xlpm.s5, SUBSTITUTE(_xlpm.s4, " bpco ", " bronchopneumopathie chronique obstructive "), _xlpm.s6, SUBSTITUTE(_xlpm.s5, " dmla ", " degenerescence maculaire liee a l age "), TRIM(_xlpm.s6))} -> diarrhée du voyageur | AF10: {=_xlfn.LET(_xlpm.base, " " & LOWER(TRIM($AE10)) & " ", _xlpm.s1, SUBSTITUTE(_xlpm.base, " omi ", " oedemes des membres inferieurs "), _xlpm.s2, SUBSTITUTE(_xlpm.s1, " idm ", " infarctus du myocarde "), _xlpm.s3, SUBSTITUTE(_xlpm.s2, " tvp ", " thrombose veineuse profonde "), _xlpm.s4, SUBSTITUTE(_xlpm.s3, " geu ", " grossesse extra-uterine "), _xlpm.s5, SUBSTITUTE(_xlpm.s4, " fuo ", " fievre d origine indeterminee "), TRIM(_xlpm.s5))} -> diarrhée du voyageur
A11: 2011 | B11: 🧪 Endocrinologie / Métabolisme | D11: 224 | E11: =IF(D11="","",IFERROR(INDEX(SSP!$E$2:$E$266, MATCH(D11, SSP!$F$2:$F$266, 0)),"")) -> Demande de bilan de santé, d’examens radiologiques ou biologiques | F11: =Feuil1!E11 -> Bilan | G11: Trouble du métabolisme du fer | H11: Hémochromatose | I11: Hépatite virale / Maladie de Wilson | J11: Homme de 50 ans, visite de contrôle à cause d'un infarctus du myocarde chez son frère. | K11: Transaminases augmentées de 3 fois. Confusion sur la cause, aucun antécédent hépatique familial, consommation d'alcool modérée. Investigation nécessaire de toutes les causes possibles. | N11: Hémochromatose | O11: =IFERROR(_xlfn.XLOOKUP($D11, SSP!$F:$F, SSP!$E:$E, "Inconnu"), "") -> Demande de bilan de santé, d’examens radiologiques ou biologiques | P11: =IF(OR(E11="", O11=""), "", IF(LOWER(E11)=LOWER(O11), "OK", "⚠️ Libellé ≠ n°")) -> OK | Q11: =IF(Feuil1!$E11="", "", IF(LOWER(Feuil1!$E11)=LOWER(E11), "Identique", "Différent")) -> Différent | R11: =IF(OR(P11="⚠️ Libellé ≠ n°", O11="Inconnu"), "⚠️", IF(Q11="Différent", "ℹ️", "")) -> ℹ️ | S11: {=_xlfn.LET(_xlpm.genCat,IFERROR(LOWER(TRIM(G11)),""),_xlpm.principal,IFERROR(LOWER(TRIM(H11)),""),_xlpm.orig,IFERROR(LOWER(TRIM(N11)),""),IF(OR(_xlpm.genCat="",_xlpm.principal=""),"",IF(LEFT(LOWER(G11),5)="autre","OK (Autre)",IF(OR(ISNUMBER(SEARCH(_xlpm.genCat,_xlpm.principal)),ISNUMBER(SEARCH(_xlpm.principal,_xlpm.genCat)),AND(_xlpm.orig<>"",OR(ISNUMBER(SEARCH(_xlpm.genCat,_xlpm.orig)),ISNUMBER(SEARCH(_xlpm.orig,_xlpm.genCat))))),"OK","⚠️ À vérifier"))))} -> ⚠️ À vérifier | T11: =IF(S11="","",IF(S11="OK (Autre)","Diagnostic générique = 'Autre – …'",IF(S11="OK","Concordance générique/principal","Écart entre générique et principal"))) -> Écart entre générique et principal | U11: {=_xlfn.LET(_xlpm.yr, A11, _xlpm.diag, IF(N11<>"", N11, H11), _xlpm.base, TRIM(SUBSTITUTE(SUBSTITUTE(SUBSTITUTE(SUBSTITUTE(_xlpm.diag,"•"," "),CHAR(160)," "),CHAR(10)," ")," "," ")), LOWER(_xlpm.yr&"|"&_xlpm.base))} -> 2011|hémochromatose | V11: =IFERROR(_xlfn.XLOOKUP($AB11,'Cas 2013-2017'!$K:$K,'Cas 2013-2017'!$D:$D,""),"") | W11: =IFERROR(_xlfn.XLOOKUP($AB11,'Cas 2013-2017'!$K:$K,'Cas 2013-2017'!$E:$E,""),"") | X11: =IFERROR(_xlfn.XLOOKUP($AB11,'Cas 2013-2017'!$K:$K,'Cas 2013-2017'!$F:$F,""),"") | Y11: =IFERROR(_xlfn.XLOOKUP($AB11,'Cas 2013-2017'!$K:$K,'Cas 2013-2017'!$G:$G,""),"") | Z11: =IFERROR(_xlfn.XLOOKUP($AB11,'Cas 2013-2017'!$K:$K,'Cas 2013-2017'!$I:$I,""),"") | AA11: =IFERROR(_xlfn.XLOOKUP($AB11,'Cas 2013-2017'!$K:$K,'Cas 2013-2017'!$H:$H,""),"") | AB11: =LOWER($A11 & "|" & $AF11) -> 2011|hémochromatose | AC11: =TRIM(SUBSTITUTE(SUBSTITUTE(SUBSTITUTE(SUBSTITUTE(" " & LOWER(TRIM(IF($N11<>"", $N11, $H11))) & " ", " aomi ", " arteriopathie des membres inferieurs "), " hta ", " hypertension arterielle "), " saos ", " syndrome d'apnees obstructives du sommeil "), " rgo ", " reflux gastro-oesophagien ") ) -> hémochromatose | AD11: =TRIM(SUBSTITUTE(SUBSTITUTE(SUBSTITUTE(SUBSTITUTE(" " & LOWER(TRIM($AC11)) & " ", " oacr ", " occlusion de l'artere centrale de la retine "), " hsd ", " hematome sous-dural "), " fa ", " fibrillation auriculaire "), " ep ", " embolie pulmonaire ") ) -> hémochromatose | AE11: {=_xlfn.LET(_xlpm.base, " " & LOWER(TRIM($AD11)) & " ", _xlpm.s1, SUBSTITUTE(_xlpm.base, " ic ", " insuffisance cardiaque "), _xlpm.s2, SUBSTITUTE(_xlpm.s1, " avc ", " accident vasculaire cerebral "), _xlpm.s3, SUBSTITUTE(_xlpm.s2, " hsa ", " hemorragie sous-arachnoidienne "), _xlpm.s4, SUBSTITUTE(_xlpm.s3, " htp ", " hypertension pulmonaire "), _xlpm.s5, SUBSTITUTE(_xlpm.s4, " bpco ", " bronchopneumopathie chronique obstructive "), _xlpm.s6, SUBSTITUTE(_xlpm.s5, " dmla ", " degenerescence maculaire liee a l age "), TRIM(_xlpm.s6))} -> hémochromatose | AF11: {=_xlfn.LET(_xlpm.base, " " & LOWER(TRIM($AE11)) & " ", _xlpm.s1, SUBSTITUTE(_xlpm.base, " omi ", " oedemes des membres inferieurs "), _xlpm.s2, SUBSTITUTE(_xlpm.s1, " idm ", " infarctus du myocarde "), _xlpm.s3, SUBSTITUTE(_xlpm.s2, " tvp ", " thrombose veineuse profonde "), _xlpm.s4, SUBSTITUTE(_xlpm.s3, " geu ", " grossesse extra-uterine "), _xlpm.s5, SUBSTITUTE(_xlpm.s4, " fuo ", " fievre d origine indeterminee "), TRIM(_xlpm.s5))} -> hémochromatose
A12: 2011 | B12: 🍴 Gastro-entérologie / Hépatologie | D12: 52 | E12: =IF(D12="","",IFERROR(INDEX(SSP!$E$2:$E$266, MATCH(D12, SSP!$F$2:$F$266, 0)),"")) -> Douleur abdominale ou épigastrique | F12: =Feuil1!E12 -> Douleur abdominale | G12: Hépatite | H12: Hépatite alcoolique | J12: Homme âgé avec douleur pressante dans l'hypocondre droit, antécédents de consommation d'alcool. | K12: Examen important et complet nécessaire. | N12: Hépatite alcoolique. | O12: =IFERROR(_xlfn.XLOOKUP($D12, SSP!$F:$F, SSP!$E:$E, "Inconnu"), "") -> Douleur abdominale ou épigastrique | P12: =IF(OR(E12="", O12=""), "", IF(LOWER(E12)=LOWER(O12), "OK", "⚠️ Libellé ≠ n°")) -> OK | Q12: =IF(Feuil1!$E12="", "", IF(LOWER(Feuil1!$E12)=LOWER(E12), "Identique", "Différent")) -> Différent | R12: =IF(OR(P12="⚠️ Libellé ≠ n°", O12="Inconnu"), "⚠️", IF(Q12="Différent", "ℹ️", "")) -> ℹ️ | S12: {=_xlfn.LET(_xlpm.genCat,IFERROR(LOWER(TRIM(G12)),""),_xlpm.principal,IFERROR(LOWER(TRIM(H12)),""),_xlpm.orig,IFERROR(LOWER(TRIM(N12)),""),IF(OR(_xlpm.genCat="",_xlpm.principal=""),"",IF(LEFT(LOWER(G12),5)="autre","OK (Autre)",IF(OR(ISNUMBER(SEARCH(_xlpm.genCat,_xlpm.principal)),ISNUMBER(SEARCH(_xlpm.principal,_xlpm.genCat)),AND(_xlpm.orig<>"",OR(ISNUMBER(SEARCH(_xlpm.genCat,_xlpm.orig)),ISNUMBER(SEARCH(_xlpm.orig,_xlpm.genCat))))),"OK","⚠️ À vérifier"))))} -> OK | T12: =IF(S12="","",IF(S12="OK (Autre)","Diagnostic générique = 'Autre – …'",IF(S12="OK","Concordance générique/principal","Écart entre générique et principal"))) -> Concordance générique/principal | U12: {=_xlfn.LET(_xlpm.yr, A12, _xlpm.diag, IF(N12<>"", N12, H12), _xlpm.base, TRIM(SUBSTITUTE(SUBSTITUTE(SUBSTITUTE(SUBSTITUTE(_xlpm.diag,"•"," "),CHAR(160)," "),CHAR(10)," ")," "," ")), LOWER(_xlpm.yr&"|"&_xlpm.base))} -> 2011|hépatite alcoolique. | V12: =IFERROR(_xlfn.XLOOKUP($AB12,'Cas 2013-2017'!$K:$K,'Cas 2013-2017'!$D:$D,""),"") | W12: =IFERROR(_xlfn.XLOOKUP($AB12,'Cas 2013-2017'!$K:$K,'Cas 2013-2017'!$E:$E,""),"") | X12: =IFERROR(_xlfn.XLOOKUP($AB12,'Cas 2013-2017'!$K:$K,'Cas 2013-2017'!$F:$F,""),"") | Y12: =IFERROR(_xlfn.XLOOKUP($AB12,'Cas 2013-2017'!$K:$K,'Cas 2013-2017'!$G:$G,""),"") | Z12: =IFERROR(_xlfn.XLOOKUP($AB12,'Cas 2013-2017'!$K:$K,'Cas 2013-2017'!$I:$I,""),"") | AA12: =IFERROR(_xlfn.XLOOKUP($AB12,'Cas 2013-2017'!$K:$K,'Cas 2013-2017'!$H:$H,""),"") | AB12: =LOWER($A12 & "|" & $AF12) -> 2011|hépatite alcoolique. | AC12: =TRIM(SUBSTITUTE(SUBSTITUTE(SUBSTITUTE(SUBSTITUTE(" " & LOWER(TRIM(IF($N12<>"", $N12, $H12))) & " ", " aomi ", " arteriopathie des membres inferieurs "), " hta ", " hypertension arterielle "), " saos ", " syndrome d'apnees obstructives du sommeil "), " rgo ", " reflux gastro-oesophagien ") ) -> hépatite alcoolique. | AD12: =TRIM(SUBSTITUTE(SUBSTITUTE(SUBSTITUTE(SUBSTITUTE(" " & LOWER(TRIM($AC12)) & " ", " oacr ", " occlusion de l'artere centrale de la retine "), " hsd ", " hematome sous-dural "), " fa ", " fibrillation auriculaire "), " ep ", " embolie pulmonaire ") ) -> hépatite alcoolique. | AE12: {=_xlfn.LET(_xlpm.base, " " & LOWER(TRIM($AD12)) & " ", _xlpm.s1, SUBSTITUTE(_xlpm.base, " ic ", " insuffisance cardiaque "), _xlpm.s2, SUBSTITUTE(_xlpm.s1, " avc ", " accident vasculaire cerebral "), _xlpm.s3, SUBSTITUTE(_xlpm.s2, " hsa ", " hemorragie sous-arachnoidienne "), _xlpm.s4, SUBSTITUTE(_xlpm.s3, " htp ", " hypertension pulmonaire "), _xlpm.s5, SUBSTITUTE(_xlpm.s4, " bpco ", " bronchopneumopathie chronique obstructive "), _xlpm.s6, SUBSTITUTE(_xlpm.s5, " dmla ", " degenerescence maculaire liee a l age "), TRIM(_xlpm.s6))} -> hépatite alcoolique. | AF12: {=_xlfn.LET(_xlpm.base, " " & LOWER(TRIM($AE12)) & " ", _xlpm.s1, SUBSTITUTE(_xlpm.base, " omi ", " oedemes des membres inferieurs "), _xlpm.s2, SUBSTITUTE(_xlpm.s1, " idm ", " infarctus du myocarde "), _xlpm.s3, SUBSTITUTE(_xlpm.s2, " tvp ", " thrombose veineuse profonde "), _xlpm.s4, SUBSTITUTE(_xlpm.s3, " geu ", " grossesse extra-uterine "), _xlpm.s5, SUBSTITUTE(_xlpm.s4, " fuo ", " fievre d origine indeterminee "), TRIM(_xlpm.s5))} -> hépatite alcoolique.
A13: 2011 | B13: Autres diagnostics / non classés | D13: 52 | E13: =IF(D13="","",IFERROR(INDEX(SSP!$E$2:$E$266, MATCH(D13, SSP!$F$2:$F$266, 0)),"")) -> Douleur abdominale ou épigastrique | F13: =Feuil1!E13 -> Douleur abdominale | G13: Autre – Autre | H13: Syndrome du côlon irritable | J13: Femme de 23 ans avec douleur abdominale, signes vitaux normaux. | K13: Douleur abdominale associée à du stress, constipation, hydratation insuffisante. Douleur améliorée après les mouvements intestinaux, aucun signe d'appendicite, examen rectal OK. | N13: Syndrome du côlon irritable | O13: =IFERROR(_xlfn.XLOOKUP($D13, SSP!$F:$F, SSP!$E:$E, "Inconnu"), "") -> Douleur abdominale ou épigastrique | P13: =IF(OR(E13="", O13=""), "", IF(LOWER(E13)=LOWER(O13), "OK", "⚠️ Libellé ≠ n°")) -> OK | Q13: =IF(Feuil1!$E13="", "", IF(LOWER(Feuil1!$E13)=LOWER(E13), "Identique", "Différent")) -> Différent | R13: =IF(OR(P13="⚠️ Libellé ≠ n°", O13="Inconnu"), "⚠️", IF(Q13="Différent", "ℹ️", "")) -> ℹ️ | S13: {=_xlfn.LET(_xlpm.genCat,IFERROR(LOWER(TRIM(G13)),""),_xlpm.principal,IFERROR(LOWER(TRIM(H13)),""),_xlpm.orig,IFERROR(LOWER(TRIM(N13)),""),IF(OR(_xlpm.genCat="",_xlpm.principal=""),"",IF(LEFT(LOWER(G13),5)="autre","OK (Autre)",IF(OR(ISNUMBER(SEARCH(_xlpm.genCat,_xlpm.principal)),ISNUMBER(SEARCH(_xlpm.principal,_xlpm.genCat)),AND(_xlpm.orig<>"",OR(ISNUMBER(SEARCH(_xlpm.genCat,_xlpm.orig)),ISNUMBER(SEARCH(_xlpm.orig,_xlpm.genCat))))),"OK","⚠️ À vérifier"))))} -> OK (Autre) | T13: =IF(S13="","",IF(S13="OK (Autre)","Diagnostic générique = 'Autre – …'",IF(S13="OK","Concordance générique/principal","Écart entre générique et principal"))) -> Diagnostic générique = 'Autre – …' | U13: {=_xlfn.LET(_xlpm.yr, A13, _xlpm.diag, IF(N13<>"", N13, H13), _xlpm.base, TRIM(SUBSTITUTE(SUBSTITUTE(SUBSTITUTE(SUBSTITUTE(_xlpm.diag,"•"," "),CHAR(160)," "),CHAR(10)," ")," "," ")), LOWER(_xlpm.yr&"|"&_xlpm.base))} -> 2011|syndrome du côlon irritable | V13: =IFERROR(_xlfn.XLOOKUP($AB13,'Cas 2013-2017'!$K:$K,'Cas 2013-2017'!$D:$D,""),"") | W13: =IFERROR(_xlfn.XLOOKUP($AB13,'Cas 2013-2017'!$K:$K,'Cas 2013-2017'!$E:$E,""),"") | X13: =IFERROR(_xlfn.XLOOKUP($AB13,'Cas 2013-2017'!$K:$K,'Cas 2013-2017'!$F:$F,""),"") | Y13: =IFERROR(_xlfn.XLOOKUP($AB13,'Cas 2013-2017'!$K:$K,'Cas 2013-2017'!$G:$G,""),"") | Z13: =IFERROR(_xlfn.XLOOKUP($AB13,'Cas 2013-2017'!$K:$K,'Cas 2013-2017'!$I:$I,""),"") | AA13: =IFERROR(_xlfn.XLOOKUP($AB13,'Cas 2013-2017'!$K:$K,'Cas 2013-2017'!$H:$H,""),"") | AB13: =LOWER($A13 & "|" & $AF13) -> 2011|syndrome du côlon irritable | AC13: =TRIM(SUBSTITUTE(SUBSTITUTE(SUBSTITUTE(SUBSTITUTE(" " & LOWER(TRIM(IF($N13<>"", $N13, $H13))) & " ", " aomi ", " arteriopathie des membres inferieurs "), " hta ", " hypertension arterielle "), " saos ", " syndrome d'apnees obstructives du sommeil "), " rgo ", " reflux gastro-oesophagien ") ) -> syndrome du côlon irritable | AD13: =TRIM(SUBSTITUTE(SUBSTITUTE(SUBSTITUTE(SUBSTITUTE(" " & LOWER(TRIM($AC13)) & " ", " oacr ", " occlusion de l'artere centrale de la retine "), " hsd ", " hematome sous-dural "), " fa ", " fibrillation auriculaire "), " ep ", " embolie pulmonaire ") ) -> syndrome du côlon irritable | AE13: {=_xlfn.LET(_xlpm.base, " " & LOWER(TRIM($AD13)) & " ", _xlpm.s1, SUBSTITUTE(_xlpm.base, " ic ", " insuffisance cardiaque "), _xlpm.s2, SUBSTITUTE(_xlpm.s1, " avc ", " accident vasculaire cerebral "), _xlpm.s3, SUBSTITUTE(_xlpm.s2, " hsa ", " hemorragie sous-arachnoidienne "), _xlpm.s4, SUBSTITUTE(_xlpm.s3, " htp ", " hypertension pulmonaire "), _xlpm.s5, SUBSTITUTE(_xlpm.s4, " bpco ", " bronchopneumopathie chronique obstructive "), _xlpm.s6, SUBSTITUTE(_xlpm.s5, " dmla ", " degenerescence maculaire liee a l age "), TRIM(_xlpm.s6))} -> syndrome du côlon irritable | AF13: {=_xlfn.LET(_xlpm.base, " " & LOWER(TRIM($AE13)) & " ", _xlpm.s1, SUBSTITUTE(_xlpm.base, " omi ", " oedemes des membres inferieurs "), _xlpm.s2, SUBSTITUTE(_xlpm.s1, " idm ", " infarctus du myocarde "), _xlpm.s3, SUBSTITUTE(_xlpm.s2, " tvp ", " thrombose veineuse profonde "), _xlpm.s4, SUBSTITUTE(_xlpm.s3, " geu ", " grossesse extra-uterine "), _xlpm.s5, SUBSTITUTE(_xlpm.s4, " fuo ", " fievre d origine indeterminee "), TRIM(_xlpm.s5))} -> syndrome du côlon irritable
A14: 2011 | B14: 👩‍🦰 Gynéco / Obstétrique / Urologie | D14: 52 | E14: =IF(D14="","",IFERROR(INDEX(SSP!$E$2:$E$266, MATCH(D14, SSP!$F$2:$F$266, 0)),"")) -> Douleur abdominale ou épigastrique | F14: =Feuil1!E14 -> Douleur abdominale | G14: Autre – Autre | H14: Endométriose | J14: Jeune femme avec dyspareunie (douleur pendant les rapports sexuels). | K14: Anamnèse : douleur abdominale, dysménorrhée sévère. Résultats : taches livides-brunâtres sur le col/vagin, sensibilité à la pression dans le cul-de-sac de Douglas. | N14: Endométriose | O14: =IFERROR(_xlfn.XLOOKUP($D14, SSP!$F:$F, SSP!$E:$E, "Inconnu"), "") -> Douleur abdominale ou épigastrique | P14: =IF(OR(E14="", O14=""), "", IF(LOWER(E14)=LOWER(O14), "OK", "⚠️ Libellé ≠ n°")) -> OK | Q14: =IF(Feuil1!$E14="", "", IF(LOWER(Feuil1!$E14)=LOWER(E14), "Identique", "Différent")) -> Différent | R14: =IF(OR(P14="⚠️ Libellé ≠ n°", O14="Inconnu"), "⚠️", IF(Q14="Différent", "ℹ️", "")) -> ℹ️ | S14: {=_xlfn.LET(_xlpm.genCat,IFERROR(LOWER(TRIM(G14)),""),_xlpm.principal,IFERROR(LOWER(TRIM(H14)),""),_xlpm.orig,IFERROR(LOWER(TRIM(N14)),""),IF(OR(_xlpm.genCat="",_xlpm.principal=""),"",IF(LEFT(LOWER(G14),5)="autre","OK (Autre)",IF(OR(ISNUMBER(SEARCH(_xlpm.genCat,_xlpm.principal)),ISNUMBER(SEARCH(_xlpm.principal,_xlpm.genCat)),AND(_xlpm.orig<>"",OR(ISNUMBER(SEARCH(_xlpm.genCat,_xlpm.orig)),ISNUMBER(SEARCH(_xlpm.orig,_xlpm.genCat))))),"OK","⚠️ À vérifier"))))} -> OK (Autre) | T14: =IF(S14="","",IF(S14="OK (Autre)","Diagnostic générique = 'Autre – …'",IF(S14="OK","Concordance générique/principal","Écart entre générique et principal"))) -> Diagnostic générique = 'Autre – …' | U14: {=_xlfn.LET(_xlpm.yr, A14, _xlpm.diag, IF(N14<>"", N14, H14), _xlpm.base, TRIM(SUBSTITUTE(SUBSTITUTE(SUBSTITUTE(SUBSTITUTE(_xlpm.diag,"•"," "),CHAR(160)," "),CHAR(10)," ")," "," ")), LOWER(_xlpm.yr&"|"&_xlpm.base))} -> 2011|endométriose | V14: =IFERROR(_xlfn.XLOOKUP($AB14,'Cas 2013-2017'!$K:$K,'Cas 2013-2017'!$D:$D,""),"") | W14: =IFERROR(_xlfn.XLOOKUP($AB14,'Cas 2013-2017'!$K:$K,'Cas 2013-2017'!$E:$E,""),"") | X14: =IFERROR(_xlfn.XLOOKUP($AB14,'Cas 2013-2017'!$K:$K,'Cas 2013-2017'!$F:$F,""),"") | Y14: =IFERROR(_xlfn.XLOOKUP($AB14,'Cas 2013-2017'!$K:$K,'Cas 2013-2017'!$G:$G,""),"") | Z14: =IFERROR(_xlfn.XLOOKUP($AB14,'Cas 2013-2017'!$K:$K,'Cas 2013-2017'!$I:$I,""),"") | AA14: =IFERROR(_xlfn.XLOOKUP($AB14,'Cas 2013-2017'!$K:$K,'Cas 2013-2017'!$H:$H,""),"") | AB14: =LOWER($A14 & "|" & $AF14) -> 2011|endométriose | AC14: =TRIM(SUBSTITUTE(SUBSTITUTE(SUBSTITUTE(SUBSTITUTE(" " & LOWER(TRIM(IF($N14<>"", $N14, $H14))) & " ", " aomi ", " arteriopathie des membres inferieurs "), " hta ", " hypertension arterielle "), " saos ", " syndrome d'apnees obstructives du sommeil "), " rgo ", " reflux gastro-oesophagien ") ) -> endométriose | AD14: =TRIM(SUBSTITUTE(SUBSTITUTE(SUBSTITUTE(SUBSTITUTE(" " & LOWER(TRIM($AC14)) & " ", " oacr ", " occlusion de l'artere centrale de la retine "), " hsd ", " hematome sous-dural "), " fa ", " fibrillation auriculaire "), " ep ", " embolie pulmonaire ") ) -> endométriose | AE14: {=_xlfn.LET(_xlpm.base, " " & LOWER(TRIM($AD14)) & " ", _xlpm.s1, SUBSTITUTE(_xlpm.base, " ic ", " insuffisance cardiaque "), _xlpm.s2, SUBSTITUTE(_xlpm.s1, " avc ", " accident vasculaire cerebral "), _xlpm.s3, SUBSTITUTE(_xlpm.s2, " hsa ", " hemorragie sous-arachnoidienne "), _xlpm.s4, SUBSTITUTE(_xlpm.s3, " htp ", " hypertension pulmonaire "), _xlpm.s5, SUBSTITUTE(_xlpm.s4, " bpco ", " bronchopneumopathie chronique obstructive "), _xlpm.s6, SUBSTITUTE(_xlpm.s5, " dmla ", " degenerescence maculaire liee a l age "), TRIM(_xlpm.s6))} -> endométriose | AF14: {=_xlfn.LET(_xlpm.base, " " & LOWER(TRIM($AE14)) & " ", _xlpm.s1, SUBSTITUTE(_xlpm.base, " omi ", " oedemes des membres inferieurs "), _xlpm.s2, SUBSTITUTE(_xlpm.s1, " idm ", " infarctus du myocarde "), _xlpm.s3, SUBSTITUTE(_xlpm.s2, " tvp ", " thrombose veineuse profonde "), _xlpm.s4, SUBSTITUTE(_xlpm.s3, " geu ", " grossesse extra-uterine "), _xlpm.s5, SUBSTITUTE(_xlpm.s4, " fuo ", " fievre d origine indeterminee "), TRIM(_xlpm.s5))} -> endométriose
A15: 2011 | B15: 🧬 Maladies infectieuses | D15: 52 | E15: =IF(D15="","",IFERROR(INDEX(SSP!$E$2:$E$266, MATCH(D15, SSP!$F$2:$F$266, 0)),"")) -> Douleur abdominale ou épigastrique | F15: =Feuil1!E15 -> Douleur abdominale | G15: Infection sexuellement transmissible | H15: IST | J15: Femme avec douleur abdominale aiguë, suspicion de IST, examen vaginal à mentionner. | K15: Assurez-vous de demander un test de grossesse en cas d'abdomen peu clair. Pensez également à une GEU. | N15: IST | O15: =IFERROR(_xlfn.XLOOKUP($D15, SSP!$F:$F, SSP!$E:$E, "Inconnu"), "") -> Douleur abdominale ou épigastrique | P15: =IF(OR(E15="", O15=""), "", IF(LOWER(E15)=LOWER(O15), "OK", "⚠️ Libellé ≠ n°")) -> OK | Q15: =IF(Feuil1!$E15="", "", IF(LOWER(Feuil1!$E15)=LOWER(E15), "Identique", "Différent")) -> Différent | R15: =IF(OR(P15="⚠️ Libellé ≠ n°", O15="Inconnu"), "⚠️", IF(Q15="Différent", "ℹ️", "")) -> ℹ️ | S15: {=_xlfn.LET(_xlpm.genCat,IFERROR(LOWER(TRIM(G15)),""),_xlpm.principal,IFERROR(LOWER(TRIM(H15)),""),_xlpm.orig,IFERROR(LOWER(TRIM(N15)),""),IF(OR(_xlpm.genCat="",_xlpm.principal=""),"",IF(LEFT(LOWER(G15),5)="autre","OK (Autre)",IF(OR(ISNUMBER(SEARCH(_xlpm.genCat,_xlpm.principal)),ISNUMBER(SEARCH(_xlpm.principal,_xlpm.genCat)),AND(_xlpm.orig<>"",OR(ISNUMBER(SEARCH(_xlpm.genCat,_xlpm.orig)),ISNUMBER(SEARCH(_xlpm.orig,_xlpm.genCat))))),"OK","⚠️ À vérifier"))))} -> ⚠️ À vérifier | T15: =IF(S15="","",IF(S15="OK (Autre)","Diagnostic générique = 'Autre – …'",IF(S15="OK","Concordance générique/principal","Écart entre générique et principal"))) -> Écart entre générique et principal | U15: {=_xlfn.LET(_xlpm.yr, A15, _xlpm.diag, IF(N15<>"", N15, H15), _xlpm.base, TRIM(SUBSTITUTE(SUBSTITUTE(SUBSTITUTE(SUBSTITUTE(_xlpm.diag,"•"," "),CHAR(160)," "),CHAR(10)," ")," "," ")), LOWER(_xlpm.yr&"|"&_xlpm.base))} -> 2011|ist | V15: =IFERROR(_xlfn.XLOOKUP($AB15,'Cas 2013-2017'!$K:$K,'Cas 2013-2017'!$D:$D,""),"") | W15: =IFERROR(_xlfn.XLOOKUP($AB15,'Cas 2013-2017'!$K:$K,'Cas 2013-2017'!$E:$E,""),"") | X15: =IFERROR(_xlfn.XLOOKUP($AB15,'Cas 2013-2017'!$K:$K,'Cas 2013-2017'!$F:$F,""),"") | Y15: =IFERROR(_xlfn.XLOOKUP($AB15,'Cas 2013-2017'!$K:$K,'Cas 2013-2017'!$G:$G,""),"") | Z15: =IFERROR(_xlfn.XLOOKUP($AB15,'Cas 2013-2017'!$K:$K,'Cas 2013-2017'!$I:$I,""),"") | AA15: =IFERROR(_xlfn.XLOOKUP($AB15,'Cas 2013-2017'!$K:$K,'Cas 2013-2017'!$H:$H,""),"") | AB15: =LOWER($A15 & "|" & $AF15) -> 2011|ist | AC15: =TRIM(SUBSTITUTE(SUBSTITUTE(SUBSTITUTE(SUBSTITUTE(" " & LOWER(TRIM(IF($N15<>"", $N15, $H15))) & " ", " aomi ", " arteriopathie des membres inferieurs "), " hta ", " hypertension arterielle "), " saos ", " syndrome d'apnees obstructives du sommeil "), " rgo ", " reflux gastro-oesophagien ") ) -> ist | AD15: =TRIM(SUBSTITUTE(SUBSTITUTE(SUBSTITUTE(SUBSTITUTE(" " & LOWER(TRIM($AC15)) & " ", " oacr ", " occlusion de l'artere centrale de la retine "), " hsd ", " hematome sous-dural "), " fa ", " fibrillation auriculaire "), " ep ", " embolie pulmonaire ") ) -> ist | AE15: {=_xlfn.LET(_xlpm.base, " " & LOWER(TRIM($AD15)) & " ", _xlpm.s1, SUBSTITUTE(_xlpm.base, " ic ", " insuffisance cardiaque "), _xlpm.s2, SUBSTITUTE(_xlpm.s1, " avc ", " accident vasculaire cerebral "), _xlpm.s3, SUBSTITUTE(_xlpm.s2, " hsa ", " hemorragie sous-arachnoidienne "), _xlpm.s4, SUBSTITUTE(_xlpm.s3, " htp ", " hypertension pulmonaire "), _xlpm.s5, SUBSTITUTE(_xlpm.s4, " bpco ", " bronchopneumopathie chronique obstructive "), _xlpm.s6, SUBSTITUTE(_xlpm.s5, " dmla ", " degenerescence maculaire liee a l age "), TRIM(_xlpm.s6))} -> ist | AF15: {=_xlfn.LET(_xlpm.base, " " & LOWER(TRIM($AE15)) & " ", _xlpm.s1, SUBSTITUTE(_xlpm.base, " omi ", " oedemes des membres inferieurs "), _xlpm.s2, SUBSTITUTE(_xlpm.s1, " idm ", " infarctus du myocarde "), _xlpm.s3, SUBSTITUTE(_xlpm.s2, " tvp ", " thrombose veineuse profonde "), _xlpm.s4, SUBSTITUTE(_xlpm.s3, " geu ", " grossesse extra-uterine "), _xlpm.s5, SUBSTITUTE(_xlpm.s4, " fuo ", " fievre d origine indeterminee "), TRIM(_xlpm.s5))} -> ist
